<?xml version="1.0"?>
<robot xmlns:xacro="http://www.ros.org/wiki/xacro"  >

    <xacro:include filename="robot_colors.xacro" />
    <xacro:include filename="inertial_macros.xacro" />

    <!-- BASE LINK -->
    <link name="base_link">
    </link>

    <!-- CHASSIS -->
    <joint name="chassis_joint" type="fixed">
        <parent link="base_link"/>
        <child link="chassis"/>
        <origin xyz="-0.1 0 0"/>
    </joint>

    <link name="chassis">
        <visual>
            <origin xyz="0.2305 0 0.089"/>
            <geometry>
                <box size="0.461 0.311 0.178"/>
            </geometry>
            <material name="white"/>
        </visual>
        <collision>
            <origin xyz="0.2305 0 0.089" rpy="0 0 0"/>
            <geometry>
                <box size="0.461 0.311 0.178"/>
            </geometry>
        </collision>
        <xacro:inertial_box mass="1.69" x="0.461" y="0.311" z="0.178">
            <origin xyz="0.2305 0 0.089" rpy="0 0 0"/>
        </xacro:inertial_box>
    </link>

    <!-- LEFT DRIVE WHEEL  -->
    <joint name="left_wheel_joint" type="continuous">
        <parent link="base_link"/>
        <child link="left_wheel"/>
        <origin xyz="0 0.175 0" rpy="-${pi/2} 0 0"/>
        <axis xyz="0 0 1"/>
    </joint>

    <link name="left_wheel">
        <visual>
            <geometry>
                <cylinder length="0.04" radius="0.05" />
            </geometry>
            <material name="orange"/>
        </visual>
        <collision>
            <geometry>
                <cylinder length="0.04" radius="0.05" />
            </geometry>
        </collision>    
        <!--NEED TO MEASURE PARAMETERS FOR WHEELS AND UPDATE-->
        <xacro:inertial_cylinder mass="0.1" length="0.04" radius="0.05">
            <origin xyz="0 0 0" rpy="0 0 0"/>
        </xacro:inertial_cylinder>
    </link>

    <!-- RIGHT DRIVE WHEEL -->

    <joint name="right_wheel_joint" type="continuous">
        <parent link="base_link"/>
        <child link="right_wheel"/>
        <origin xyz="0 -0.175 0" rpy="${pi/2} 0 0"/>
        <axis xyz="0 0 -1"/>
    </joint>

    <link name="right_wheel">
        <visual>
            <geometry>
                <cylinder length="0.04" radius="0.05" />
            </geometry>
            <material name="orange"/>
        </visual>
        <collision>
            <geometry>
                <cylinder length="0.04" radius="0.05" />
            </geometry>
        </collision>
        <!--NEED TO MEASURE PARAMETERS FOR WHEELS AND UPDATE-->
        <xacro:inertial_cylinder mass="0.1" length="0.04" radius="0.05">
            <origin xyz="0 0 0" rpy="0 0 0"/>
        </xacro:inertial_cylinder>        
    </link>

    <!-- CASTER WHEEL -->
    <!-- CREATE TWO CASTER WHEELS LATER-->
    <joint name="caster_wheel_joint" type="fixed">
        <parent link="chassis"/>
        <child link="caster_wheel"/>
        <origin xyz="0.24 0 0" rpy="0 0 0"/>
    </joint>
    
    <!--UPDATE THIS TO CYLINDER ONCE PARAMETERS FOR WHEELS IS MEASURED-->
    <link name="caster_wheel">
        <visual>
            <geometry>
                <sphere radius="0.05" />
            </geometry>
            <material name="orange"/>
        </visual>
        <collision>
            <geometry>
                <sphere radius="0.05" />
            </geometry>
        </collision>
        <!--UPDATE THIS TO CYLINDER ONCE PARAMETERS FOR WHEELS IS MEASURED-->
        <xacro:inertial_sphere mass="0.1" radius="0.05">
            <origin xyz="0 0 0" rpy="0 0 0"/>
        </xacro:inertial_sphere>
    </link>


</robot>